Workbook

Sheet Sheet2
A3: Row Labels | B3: Count of date
A4: Рябко Сергей Сергеевич | B4: 17 | C4: =_xlfn.XLOOKUP(A4,Sheet1!B:B,Sheet1!C:C,"") -> ДРЗА ВН
A5: Воропаев Александр Юрьевич | B5: 17 | C5: =_xlfn.XLOOKUP(A5,Sheet1!B:B,Sheet1!C:C,"") -> ДАЭС
A6: Четырева Наталья Владимировна | B6: 11 | C6: =_xlfn.XLOOKUP(A6,Sheet1!B:B,Sheet1!C:C,"") -> Редкит Лаб
A7: Москалев Алексей Анатольевич | B7: 10 | C7: ДАЭС
A8: Егорова Елена Игоревна | B8: 10 | C8: =_xlfn.XLOOKUP(A8,Sheet1!B:B,Sheet1!C:C,"") -> Цех монтажа печатных плат
A9: Маслаков Алексей Васильевич | B9: 10 | C9: =_xlfn.XLOOKUP(A9,Sheet1!B:B,Sheet1!C:C,"") -> ДАЭС
A10: Боярских Дмитрий Вячеславович | B10: 9 | C10: =_xlfn.XLOOKUP(A10,Sheet1!B:B,Sheet1!C:C,"") -> ДАЭС
A11: Базанова Наталья Владимировна | B11: 8 | C11: Юридическо-договорной отдел
A12: Разумов Артем Николаевич | B12: 8 | C12: ДРЗА ВН
A13: Хусяинов Ильяс Зякиевич | B13: 8 | C13: =_xlfn.XLOOKUP(A13,Sheet1!B:B,Sheet1!C:C,"") -> ДАЭС
A14: Селиванов Артём Петрович | B14: 7 | C14: =_xlfn.XLOOKUP(A14,Sheet1!B:B,Sheet1!C:C,"") -> ДАЭС
A15: Васильев Игорь Сергеевич | B15: 7 | C15: ДРЗА ВН
A16: Ульянов Александр Иванович | B16: 6 | C16: =_xlfn.XLOOKUP(A16,Sheet1!B:B,Sheet1!C:C,"") -> ДАЭС
A17: Овчаров Иван Олегович | B17: 6 | C17: =_xlfn.XLOOKUP(A17,Sheet1!B:B,Sheet1!C:C,"") -> ДРЗА ВН
A18: Ганина (Абрамова) Екатерина Павловна | B18: 6 | C18: =_xlfn.XLOOKUP(A18,Sheet1!B:B,Sheet1!C:C,"") -> Отдел ИТ
A19: Полушин Андрей Владимирович | B19: 6 | C19: =_xlfn.XLOOKUP(A19,Sheet1!B:B,Sheet1!C:C,"") -> ДАЭС
A20: Лешко Антон Сергеевич | B20: 6 | C20: =_xlfn.XLOOKUP(A20,Sheet1!B:B,Sheet1!C:C,"") -> Редкит Лаб
A21: Патрушева Татьяна Анатольевна | B21: 5 | C21: =_xlfn.XLOOKUP(A21,Sheet1!B:B,Sheet1!C:C,"") -> Дирекция
A22: Агафонова Виктория Александровна | B22: 5 | C22: =_xlfn.XLOOKUP(A22,Sheet1!B:B,Sheet1!C:C,"") -> Цех монтажа печатных плат
A23: Кухаренко Виктор Александрович | B23: 5 | C23: =_xlfn.XLOOKUP(A23,Sheet1!B:B,Sheet1!C:C,"") -> Отдел эксплуатации и капитального строительства зданий и сооружений (ОЭКС)
A24: Грязнов Алексей Олегович | B24: 5 | C24: =_xlfn.XLOOKUP(A24,Sheet1!B:B,Sheet1!C:C,"") -> ДАЭС
A25: Бабаев Артем Ахмадалиевич | B25: 4 | C25: =_xlfn.XLOOKUP(A25,Sheet1!B:B,Sheet1!C:C,"") -> Редкит Лаб
A26: Егармин Павел Сергеевич | B26: 4 | C26: =_xlfn.XLOOKUP(A26,Sheet1!B:B,Sheet1!C:C,"") -> ДАЭС
A27: Драничникова Любовь Александровна | B27: 4 | C27: =_xlfn.XLOOKUP(A27,Sheet1!B:B,Sheet1!C:C,"") -> Цех монтажа печатных плат
A28: Макаров Евгений Анатольевич | B28: 4 | C28: Редкит Лаб
A29: Фридрих Юрий Николаевич | B29: 4 | C29: =_xlfn.XLOOKUP(A29,Sheet1!B:B,Sheet1!C:C,"") -> Цех монтажа печатных плат
A30: Подашевский Евгений Михайлович | B30: 4 | C30: ДАЭС
A31: Шаблов Иван Александрович | B31: 4 | C31: =_xlfn.XLOOKUP(A31,Sheet1!B:B,Sheet1!C:C,"") -> Испытательный центр
A32: Зиберт Дмитрий Евгеньевич | B32: 4 | C32: ДАЭС
A33: Сентябова Елена Андреевна | B33: 3 | C33: =_xlfn.XLOOKUP(A33,Sheet1!B:B,Sheet1!C:C,"") -> ДАЭС
A34: Григорьева Александра Сергеевна | B34: 3 | C34: Кадровая служба
A35: Топайкина Татьяна Васильевна | B35: 3 | C35: =_xlfn.XLOOKUP(A35,Sheet1!B:B,Sheet1!C:C,"") -> Кадровая служба
A36: Иванов Юрий Васильевич | B36: 3 | C36: НИЦ Прософт-Системы
A37: Шевченко Вера Михайловна | B37: 3 | C37: Отдел маркетинга и рекламы
A38: Ченцов Олег Олегович | B38: 3 | C38: =_xlfn.XLOOKUP(A38,Sheet1!B:B,Sheet1!C:C,"") -> ДАЭС
A39: Ткач Евгений Игоревич | B39: 3 | C39: =_xlfn.XLOOKUP(A39,Sheet1!B:B,Sheet1!C:C,"") -> ДРЗА ВН
A40: Косенко Алексей Николаевич | B40: 3 | C40: Склад и отдел транспортной логистики
A41: Николаев Павел Вадимович | B41: 3 | C41: Редкит Лаб
A42: Диордиев Андрей Анатольевич | B42: 3 | C42: =_xlfn.XLOOKUP(A42,Sheet1!B:B,Sheet1!C:C,"") -> ДАЭС
...

Sheet Sheet1
A1: chat_id | B1: fio | C1: department | D1: nominee | E1: date
A2: 827617660 | B2: Коновалов Николай Сергеевич | C2: Склад и отдел транспортной логистики | D2: Иванчов Дмитрий Петрович | E2: 2025-11-17T14:03:10.776429
A3: 1014105388 | B3: Зайнутдинов Валерий Игоревич | C3: ДАЭС | D3: Барышев Роман Юрьевич | E3: 2025-11-17T14:03:25.877747
A4: 1263768779 | B4: Фуфаров Данил Валерьевич | C4: ДАЭС | D4: Воропаев Александр Юрьевич | E4: 2025-11-17T14:04:17.613670
A5: 1696116239 | B5: Долгих Елена Олеговна | C5: Отдел закупок | D5: Гиндуллин Руслан Азатович | E5: 2025-11-17T14:04:24.380989
A6: 1909442531 | B6: Дмитриев Евгений Андреевич | C6: Отдел закупок | D6: Озорнин Иван Егорович | E6: 2025-11-17T14:04:40.364691
A7: 2021077720 | B7: Галиева Ольга Степановна | C7: Кадровая служба | D7: Топайкина Татьяна Васильевна | E7: 2025-11-17T14:05:08.516306
A8: 1041279690 | B8: Зайцева Наталья Михайловна | C8: Кадровая служба | D8: Андреевских Вера Валерьевна | E8: 2025-11-17T14:05:42.458044
A9: 1328835489 | B9: Суздалов Всеволод Вячеславович | C9: ДАЭС | D9: Воропаев Александр Юрьевич | E9: 2025-11-17T14:05:55.175662
A10: 552510694 | B10: Соловьёв Константин Михайлович | C10: Редкит Лаб | D10: Николаев Павел Вадимович | E10: 2025-11-17T14:06:22.997118
A11: 1127193219 | B11: Егошин Иван Евгеньевич | C11: Редкит Лаб | D11: Кочнева Елена Сергеевна | E11: 2025-11-17T14:09:46.382223
A12: 678618769 | B12: Бабаев Артем Ахмадалиевич | C12: Редкит Лаб | D12: Лешко Антон Сергеевич | E12: 2025-11-17T14:11:33.338746
A13: 468465382 | B13: Абрамов Роман Павлович | C13: Редкит Лаб | D13: Сумарев Алексей Леонидович | E13: 2025-11-17T14:12:19.143411
... A465: 1337718703 | B465: Колокольников Данила Игоревич | C465: Отдел энергосвязи | D465: Багун Максим Сергеевич | E465: 2025-11-25T20:10:43.589386
B466: Берденева (Прокудина) Ольга Васильевна | C466: РегЛаб: ДИР: Отдел разработки системного ПО | D466: Щербаков Сергей Викторович | E466: 2025-11-24T15:46:03.637425
B467: Фролов Евгений Александрович | C467: РегЛаб: ДИР: Отдел разработки системного ПО | D467: Коваленко Андрей Сергеевич | E467: 2025-11-24T15:46:03.637426
B468: Бараковских Екатерина Николаевна | C468: Корпоративный отдел продаж | D468: Меньшиков Сергей Борисович | E468: 2025-11-24T15:46:03.637427
B469: Макаров Константин Альбертович | C469: Редкит Лаб | D469: Бабаев Артем Ахмадалиевич | E469: 2025-11-24T15:46:03.637428
B470: Брызгалов Сергей Александрович | C470: Отдел эксплуатации и капитального строительства зданий и сооружений (ОЭКС) | D470: Кухаренко Виктор Александрович | E470: 2025-11-24T15:46:03.637429
B471: Мозоваткин Василий Иванович | C471: Отдел ИТ | D471: Ганина (Абрамова) Екатерина Павловна | E471: 2025-11-24T15:46:03.637430
